Workbook

Sheet daily_food_nutrition_dataset.cs
A1: Food_Item | B1: Food_Item_VN | C1: Category | D1: Category_VN | E1: Calories (kcal) | F1: Protein (g) | G1: Carbohydrates (g) | H1: Fat (g) | I1: Fiber (g) | J1: Sugars (g) | K1: Sodium (mg) | L1: Cholesterol (mg) | M1: Meal_Type | N1: Water_Intake (ml)
A2: Scrambled Eggs (2 large) | B2: Trứng chiên (2 quả lớn) | C2: Protein/Dairy | D2: =IFERROR( VLOOKUP(C2, category_map!A:B, 2, FALSE), C2 ) -> Chất đạm/Sữa | E2: 180 | F2: 12 | G2: 2 | H2: 14 | I2: 0 | J2: 1 | K2: 180 | L2: 370 | M2: Breakfast | N2: 250
A3: Whole Wheat Toast (1 slice) | B3: Bánh mì nướng lúa mì nguyên hạt (1 lát) | C3: Grain | D3: =IFERROR( VLOOKUP(C3, category_map!A:B, 2, FALSE), C3 ) -> Ngũ cốc | E3: 80 | F3: 4 | G3: 14 | H3: 1 | I3: 2 | J3: 2 | K3: 140 | L3: 0 | M3: Breakfast | N3: 0
A4: Coffee (black) | B4: Cà phê đen (không đường) | C4: Beverage | D4: =IFERROR( VLOOKUP(C4, category_map!A:B, 2, FALSE), C4 ) -> Đồ uống | E4: 5 | F4: 0.3 | G4: 0 | H4: 0.1 | I4: 0 | J4: 0 | K4: 5 | L4: 0 | M4: Breakfast | N4: 0
A5: Banana | B5: Chuối | C5: Fruit | D5: =IFERROR( VLOOKUP(C5, category_map!A:B, 2, FALSE), C5 ) -> Trái cây | E5: 105 | F5: 46082 | G5: 27 | H5: 0.4 | I5: 46025 | J5: 14 | K5: 1 | L5: 0 | M5: Breakfast | N5: 0
A6: Grilled Chicken Salad | B6: Gỏi Gà Nướng | C6: Meal/Protein | D6: =IFERROR( VLOOKUP(C6, category_map!A:B, 2, FALSE), C6 ) -> Bữa ăn/Chất đạm | E6: 350 | F6: 30 | G6: 10 | H6: 20 | I6: 5 | J6: 4 | K6: 400 | L6: 80 | M6: Lunch | N6: 500
A7: Apple | B7: Táo | C7: Fruit | D7: =IFERROR( VLOOKUP(C7, category_map!A:B, 2, FALSE), C7 ) -> Trái cây | E7: 95 | F7: 0.5 | G7: 25 | H7: 0.3 | I7: 46116 | J7: 19 | K7: 2 | L7: 0 | M7: Snack | N7: 0
A8: Salmon (4oz grilled) | B8: Cá hồi (113 gram nướng) | C8: Protein/Fish | D8: =IFERROR( VLOOKUP(C8, category_map!A:B, 2, FALSE), C8 ) -> Chất đạm/Cá | E8: 230 | F8: 25 | G8: 0 | H8: 14 | I8: 0 | J8: 0 | K8: 60 | L8: 60 | M8: Dinner | N8: 250
A9: Quinoa (1 cup cooked) | B9: Hạt Diêm Mạch (185 gram đã nấu) | C9: Grain | D9: =IFERROR( VLOOKUP(C9, category_map!A:B, 2, FALSE), C9 ) -> Ngũ cốc | E9: 222 | F9: 8 | G9: 39 | H9: 46176 | I9: 5 | J9: 1 | K9: 13 | L9: 0 | M9: Dinner | N9: 0
A10: Steamed Broccoli (1 cup) | B10: Bông cải xanh hấp (120 gram) | C10: Vegetable | D10: =IFERROR( VLOOKUP(C10, category_map!A:B, 2, FALSE), C10 ) -> Rau củ | E10: 55 | F10: 46206 | G10: 46064 | H10: 0.6 | I10: 46027 | J10: 2 | K10: 40 | L10: 0 | M10: Dinner | N10: 0
A11: Greek Yogurt (plain 1 cup) | B11: Sữa Chua Hy Lạp (nguyên chất, 240g) | C11: Dairy | D11: =IFERROR( VLOOKUP(C11, category_map!A:B, 2, FALSE), C11 ) -> Sản phẩm từ sữa | E11: 150 | F11: 25 | G11: 8 | H11: 3 | I11: 0 | J11: 7 | K11: 85 | L11: 10 | M11: Snack | N11: 250
A12: Oatmeal (1 cup cooked) | B12: Bột yến mạch (240 gram đã nấu chín) | C12: Grain | D12: =IFERROR( VLOOKUP(C12, category_map!A:B, 2, FALSE), C12 ) -> Ngũ cốc | E12: 160 | F12: 6 | G12: 28 | H12: 3 | I12: 4 | J12: 1 | K12: 2 | L12: 0 | M12: Breakfast | N12: 250
A13: Blueberries (1/2 cup) | B13: Quả việt quất (74 g) | C13: Fruit | D13: =IFERROR( VLOOKUP(C13, category_map!A:B, 2, FALSE), C13 ) -> Trái cây | E13: 42 | F13: 0.5 | G13: 11 | H13: 0.2 | I13: 46235 | J13: 7 | K13: 1 | L13: 0 | M13: Breakfast | N13: 0
A14: Almonds (1 oz) | B14: Hạnh nhân (28.35 g) | C14: Nut | D14: =IFERROR( VLOOKUP(C14, category_map!A:B, 2, FALSE), C14 ) -> Hạt | E14: 164 | F14: 6 | G14: 6 | H14: 14 | I14: 46145 | J14: 1 | K14: 1 | L14: 0 | M14: Snack | N14: 0
A15: Turkey Sandwich (on wheat) | B15: Bánh Mì Thổ Nhĩ Kỳ (bánh mì lúa mì nguyên cám) | C15: Meal/Processed | D15: =IFERROR( VLOOKUP(C15, category_map!A:B, 2, FALSE), C15 ) -> Bữa ăn/Chế biến | E15: 340 | F15: 22 | G15: 34 | H15: 12 | I15: 5 | J15: 6 | K15: 850 | L15: 50 | M15: Lunch | N15: 500
A16: Carrot Sticks (1 cup) | B16: Cà rốt dạng que (237 ml) | C16: Vegetable | D16: =IFERROR( VLOOKUP(C16, category_map!A:B, 2, FALSE), C16 ) -> Rau củ | E16: 52 | F16: 46054 | G16: 46093 | H16: 0.3 | I16: 46176 | J16: 6 | K16: 88 | L16: 0 | M16: Snack | N16: 0
A17: Spaghetti Bolognese | B17: Mì Ý Sốt Thịt Bò Bằm (Bolognese) | C17: Meal/Pasta | D17: =IFERROR( VLOOKUP(C17, category_map!A:B, 2, FALSE), C17 ) -> Bữa ăn/Mì ống | E17: 460 | F17: 20 | G17: 55 | H17: 18 | I17: 6 | J17: 10 | K17: 700 | L17: 50 | M17: Dinner | N17: 250
A18: Side Salad (light dressing) | B18: Salad phụ (sốt trộn ít béo) | C18: Vegetable | D18: =IFERROR( VLOOKUP(C18, category_map!A:B, 2, FALSE), C18 ) -> Rau củ | E18: 70 | F18: 2 | G18: 8 | H18: 4 | I18: 3 | J18: 3 | K18: 150 | L18: 0 | M18: Dinner | N18: 0
A19: Protein Shake (Whey) | B19: Thức uống bổ sung protein (Whey) | C19: Supplement | D19: =IFERROR( VLOOKUP(C19, category_map!A:B, 2, FALSE), C19 ) -> Thực phẩm bổ sung | E19: 120 | F19: 24 | G19: 3 | H19: 1 | I19: 1 | J19: 2 | K19: 160 | L19: 5 | M19: Snack | N19: 500
A20: Cereal (Frosted Flakes 1 cup) | B20: Ngũ cốc (Frosted Flakes, khẩu phần 240 ml) | C20: Grain/Processed | D20: =IFERROR( VLOOKUP(C20, category_map!A:B, 2, FALSE), C20 ) -> Ngũ cốc/Chế biến | E20: 130 | F20: 2 | G20: 31 | H20: 0 | I20: 1 | J20: 11 | K20: 190 | L20: 0 | M20: Breakfast | N20: 0
A21: Milk (2% 1 cup) | B21: Sữa giảm béo 2% (240ml) | C21: Dairy | D21: =IFERROR( VLOOKUP(C21, category_map!A:B, 2, FALSE), C21 ) -> Sản phẩm từ sữa | E21: 122 | F21: 8 | G21: 12 | H21: 5 | I21: 0 | J21: 12 | K21: 100 | L21: 20 | M21: Breakfast | N21: 0
A22: Lentil Soup (1 can) | B22: Súp Đậu Lăng (1 lon) | C22: Meal/Legume | D22: =IFERROR( VLOOKUP(C22, category_map!A:B, 2, FALSE), C22 ) -> Bữa ăn/Đậu | E22: 230 | F22: 15 | G22: 35 | H22: 3 | I22: 12 | J22: 6 | K22: 650 | L22: 0 | M22: Lunch | N22: 250
A23: White Rice (1 cup cooked) | B23: Cơm trắng (186 g, đã nấu) | C23: Grain | D23: =IFERROR( VLOOKUP(C23, category_map!A:B, 2, FALSE), C23 ) -> Ngũ cốc | E23: 204 | F23: 46057 | G23: 44.5 | H23: 0.4 | I23: 0.6 | J23: 0.1 | K23: 2 | L23: 0 | M23: Dinner | N23: 0
A24: Tofu Stir-fry | B24: Đậu phụ xào | C24: Meal/Vegetarian | D24: =IFERROR( VLOOKUP(C24, category_map!A:B, 2, FALSE), C24 ) -> Bữa ăn/Chay | E24: 400 | F24: 18 | G24: 30 | H24: 22 | I24: 7 | J24: 9 | K24: 500 | L24: 0 | M24: Dinner | N24: 250
A25: Orange | B25: Quả Cam | C25: Fruit | D25: =IFERROR( VLOOKUP(C25, category_map!A:B, 2, FALSE), C25 ) -> Trái cây | E25: 62 | F25: 46054 | G25: 46127 | H25: 0.2 | I25: 46025 | J25: 12 | K25: 0 | L25: 0 | M25: Snack | N25: 0
A26: Bagel (plain) | B26: Bánh mì vòng (thường) | C26: Grain | D26: =IFERROR( VLOOKUP(C26, category_map!A:B, 2, FALSE), C26 ) -> Ngũ cốc | E26: 270 | F26: 11 | G26: 55 | H26: 46143 | I26: 2 | J26: 5 | K26: 430 | L26: 0 | M26: Breakfast | N26: 250
A27: Cream Cheese (2 tbsp) | B27: Phô mai kem (khoảng 34 g) | C27: Dairy | D27: =IFERROR( VLOOKUP(C27, category_map!A:B, 2, FALSE), C27 ) -> Sản phẩm từ sữa | E27: 100 | F27: 2 | G27: 2 | H27: 10 | I27: 0 | J27: 1 | K27: 90 | L27: 30 | M27: Breakfast | N27: 0
A28: Tuna Salad (1/2 cup) | B28: Salad Cá Ngừ (1,2 dl) | C28: Meal/Fish | D28: =IFERROR( VLOOKUP(C28, category_map!A:B, 2, FALSE), C28 ) -> Bữa ăn/Cá | E28: 190 | F28: 19 | G28: 2 | H28: 12 | I28: 1 | J28: 1 | K28: 400 | L28: 30 | M28: Lunch | N28: 500
A29: Crackers (5 whole wheat) | B29: Bánh quy giòn (5 chiếc, làm từ lúa mì nguyên hạt) | C29: Grain/Processed | D29: =IFERROR( VLOOKUP(C29, category_map!A:B, 2, FALSE), C29 ) -> Ngũ cốc/Chế biến | E29: 90 | F29: 2 | G29: 14 | H29: 3 | I29: 2 | J29: 0 | K29: 180 | L29: 0 | M29: Lunch | N29: 0
A30: Beef Steak (6oz sirloin) | B30: Bít tết bò (thăn nội 170g) | C30: Protein/Meat | D30: =IFERROR( VLOOKUP(C30, category_map!A:B, 2, FALSE), C30 ) -> Chất đạm/Thịt | E30: 270 | F30: 42 | G30: 0 | H30: 10 | I30: 0 | J30: 0 | K30: 90 | L30: 115 | M30: Dinner | N30: 250
A31: Baked Potato (medium) | B31: Khoai tây nướng (cỡ trung bình) | C31: Vegetable | D31: =IFERROR( VLOOKUP(C31, category_map!A:B, 2, FALSE), C31 ) -> Rau củ | E31: 160 | F31: 46085 | G31: 36 | H31: 0.2 | I31: 46237 | J31: 1 | K31: 17 | L31: 0 | M31: Dinner | N31: 0
A32: Ice Cream (1/2 cup vanilla) | B32: Kem Vani (65 g) | C32: Dairy/Dessert | D32: =IFERROR( VLOOKUP(C32, category_map!A:B, 2, FALSE), C32 ) -> Sữa/Tráng miệng | E32: 145 | F32: 46144 | G32: 17 | H32: 46149 | I32: 0.5 | J32: 16 | K32: 55 | L32: 30 | M32: Snack | N32: 0
A33: Pizza (1 slice pepperoni) | B33: Pizza (1 lát pepperoni) | C33: Meal/Processed | D33: =IFERROR( VLOOKUP(C33, category_map!A:B, 2, FALSE), C33 ) -> Bữa ăn/Chế biến | E33: 290 | F33: 12 | G33: 34 | H33: 12 | I33: 2 | J33: 4 | K33: 720 | L33: 35 | M33: Dinner | N33: 250
A34: Avocado Toast (1 slice) | B34: Bánh mì nướng bơ (1 lát) | C34: Meal/Vegetarian | D34: =IFERROR( VLOOKUP(C34, category_map!A:B, 2, FALSE), C34 ) -> Bữa ăn/Chay | E34: 260 | F34: 7 | G34: 28 | H34: 15 | I34: 10 | J34: 1 | K34: 350 | L34: 0 | M34: Breakfast | N34: 500
A35: Hard-Boiled Egg (1 large) | B35: Trứng Gà Luộc Chín (1 quả lớn) | C35: Protein | D35: =IFERROR( VLOOKUP(C35, category_map!A:B, 2, FALSE), C35 ) -> Chất đạm | E35: 78 | F35: 46087 | G35: 0.6 | H35: 46086 | I35: 0 | J35: 0.5 | K35: 62 | L35: 187 | M35: Snack | N35: 0
A36: Chicken Wrap (with tortilla) | B36: Bánh Cuộn Gà (kèm vỏ bánh tortilla) | C36: Meal/Processed | D36: =IFERROR( VLOOKUP(C36, category_map!A:B, 2, FALSE), C36 ) -> Bữa ăn/Chế biến | E36: 410 | F36: 25 | G36: 38 | H36: 17 | I36: 5 | J36: 3 | K36: 780 | L36: 60 | M36: Lunch | N36: 250
A37: Grapes (1 cup) | B37: Nho (150 gram) | C37: Fruit | D37: =IFERROR( VLOOKUP(C37, category_map!A:B, 2, FALSE), C37 ) -> Trái cây | E37: 104 | F37: 46023 | G37: 27 | H37: 0.2 | I37: 46113 | J37: 23 | K37: 3 | L37: 0 | M37: Snack | N37: 0
A38: Cottage Cheese (1/2 cup) | B38: Phô mai Cottage (khoảng 120 ml) | C38: Dairy | D38: =IFERROR( VLOOKUP(C38, category_map!A:B, 2, FALSE), C38 ) -> Sản phẩm từ sữa | E38: 90 | F38: 12 | G38: 5 | H38: 3 | I38: 0 | J38: 4 | K38: 400 | L38: 10 | M38: Snack | N38: 0
A39: Burger (cheeseburger) | B39: Bánh mì kẹp thịt bò (thịt bò và phô mai) | C39: Meal/Processed | D39: =IFERROR( VLOOKUP(C39, category_map!A:B, 2, FALSE), C39 ) -> Bữa ăn/Chế biến | E39: 550 | F39: 30 | G39: 40 | H39: 30 | I39: 3 | J39: 7 | K39: 1100 | L39: 90 | M39: Dinner | N39: 500
A40: French Fries (medium) | B40: Khoai tây chiên (cỡ vừa) | C40: Vegetable/Processed | D40: =IFERROR( VLOOKUP(C40, category_map!A:B, 2, FALSE), C40 ) -> Rau củ/Chế biến | E40: 340 | F40: 4 | G40: 44 | H40: 17 | I40: 4 | J40: 0.3 | K40: 230 | L40: 0 | M40: Dinner | N40: 0
...

Sheet category_map
A1: Category (EN) | B1: Category (VI)
A2: Protein/Dairy | B2: Chất đạm/Sữa
A3: Grain | B3: Ngũ cốc
A4: Beverage | B4: Đồ uống
A5: Fruit | B5: Trái cây
A6: Meal/Protein | B6: Bữa ăn/Chất đạm
A7: Protein/Fish | B7: Chất đạm/Cá
A8: Vegetable | B8: Rau củ
A9: Dairy | B9: Sản phẩm từ sữa
A10: Nut | B10: Hạt
A11: Meal/Processed | B11: Bữa ăn/Chế biến
A12: Meal/Pasta | B12: Bữa ăn/Mì ống
... A47: Snack/Appetizer | B47: Đồ ăn nhẹ/Khai vị
